Traceback (most recent call last):
  File "getDashboard.py", line 1, in <module>
    import requests
ImportError: No module named requests
Traceback (most recent call last):
  File "getDashboard.py", line 1, in <module>
    import requests
ImportError: No module named requests
Traceback (most recent call last):
  File "getDashboard.py", line 1, in <module>
    import requests
ImportError: No module named requests
Traceback (most recent call last):
  File "getDashboard.py", line 1, in <module>
    import requests
ImportError: No module named requests
Traceback (most recent call last):
  File "getDashboard.py", line 1, in <module>
    import requests
ImportError: No module named requests
same
changed
same
changed
same
same
same
same
same
same
same
same
same
same
same
same
same
same
same
same
same
same
same
same
same
same
same
same
same
same
same
same
same
same
same
changed
same
same
same
same
same
same
same
same
same
same
same
same
same
same
changed
same
same
same
same
same
same
same
same
same
same
same
same
same
same
same
same
same
same
same
same
same
same
same
same
same
same
same
same
same
same
same
same
same
same
same
same
same
same
same
same
same
same
same
same
same
same
same
same
same
same
same
same
same
same
same
same
same
same
same
same
same
same
same
same
same
same
same
same
same
same
same
same
changed
same
same
same
same
same
Traceback (most recent call last):
  File "/home/danb/miniconda3/lib/python3.8/site-packages/urllib3/contrib/pyopenssl.py", line 313, in recv_into
    return self.connection.recv_into(*args, **kwargs)
  File "/home/danb/miniconda3/lib/python3.8/site-packages/OpenSSL/SSL.py", line 1840, in recv_into
    self._raise_ssl_error(self._ssl, result)
  File "/home/danb/miniconda3/lib/python3.8/site-packages/OpenSSL/SSL.py", line 1663, in _raise_ssl_error
    raise SysCallError(errno, errorcode.get(errno))
OpenSSL.SSL.SysCallError: (104, 'ECONNRESET')

During handling of the above exception, another exception occurred:

Traceback (most recent call last):
  File "/home/danb/miniconda3/lib/python3.8/site-packages/urllib3/response.py", line 425, in _error_catcher
    yield
  File "/home/danb/miniconda3/lib/python3.8/site-packages/urllib3/response.py", line 752, in read_chunked
    self._update_chunk_length()
  File "/home/danb/miniconda3/lib/python3.8/site-packages/urllib3/response.py", line 682, in _update_chunk_length
    line = self._fp.fp.readline()
  File "/home/danb/miniconda3/lib/python3.8/socket.py", line 669, in readinto
    return self._sock.recv_into(b)
  File "/home/danb/miniconda3/lib/python3.8/site-packages/urllib3/contrib/pyopenssl.py", line 318, in recv_into
    raise SocketError(str(e))
OSError: (104, 'ECONNRESET')

During handling of the above exception, another exception occurred:

Traceback (most recent call last):
  File "/home/danb/miniconda3/lib/python3.8/site-packages/requests/models.py", line 751, in generate
    for chunk in self.raw.stream(chunk_size, decode_content=True):
  File "/home/danb/miniconda3/lib/python3.8/site-packages/urllib3/response.py", line 560, in stream
    for line in self.read_chunked(amt, decode_content=decode_content):
  File "/home/danb/miniconda3/lib/python3.8/site-packages/urllib3/response.py", line 781, in read_chunked
    self._original_response.close()
  File "/home/danb/miniconda3/lib/python3.8/contextlib.py", line 131, in __exit__
    self.gen.throw(type, value, traceback)
  File "/home/danb/miniconda3/lib/python3.8/site-packages/urllib3/response.py", line 443, in _error_catcher
    raise ProtocolError("Connection broken: %r" % e, e)
urllib3.exceptions.ProtocolError: ('Connection broken: OSError("(104, \'ECONNRESET\')")', OSError("(104, 'ECONNRESET')"))

During handling of the above exception, another exception occurred:

Traceback (most recent call last):
  File "getDashboard.py", line 81, in <module>
    r2 = session.post(url, json=payload, headers=header)
  File "/home/danb/miniconda3/lib/python3.8/site-packages/requests/sessions.py", line 578, in post
    return self.request('POST', url, data=data, json=json, **kwargs)
  File "/home/danb/miniconda3/lib/python3.8/site-packages/requests/sessions.py", line 530, in request
    resp = self.send(prep, **send_kwargs)
  File "/home/danb/miniconda3/lib/python3.8/site-packages/requests/sessions.py", line 683, in send
    r.content
  File "/home/danb/miniconda3/lib/python3.8/site-packages/requests/models.py", line 829, in content
    self._content = b''.join(self.iter_content(CONTENT_CHUNK_SIZE)) or b''
  File "/home/danb/miniconda3/lib/python3.8/site-packages/requests/models.py", line 754, in generate
    raise ChunkedEncodingError(e)
requests.exceptions.ChunkedEncodingError: ('Connection broken: OSError("(104, \'ECONNRESET\')")', OSError("(104, 'ECONNRESET')"))
same
same
same
same
same
same
same
same
same
same
same
same
same
same
same
same
same
same
same
same
same
same
same
same
same
same
same
same
same
same
same
same
same
same
same
same
same
same
same
same
same
same
same
same
same
same
same
same
same
same
same
same
same
same
same
same
same
same
same
same
same
same
same
same
same
same
same
same
same
same
same
same
same
same
same
same
same
same
same
same
same
same
same
same
same
same
same
same
same
same
same
same
same
same
same
same
same
same
same
same
changed
same
same
same
same
same
same
same
same
same
changed
same
same
same
same
same
same
same
same
same
same
same
same
same
same
same
same
same
same
same
same
same
same
same
same
same
same
same
same
same
same
same
same
same
same
same
changed
same
same
same
same
same
same
same
same
same
same
same
same
changed
same
same
same
same
same
same
same
same
same
same
same
same
same
same
same
same
same
same
same
same
same
same
same
same
same
same
same
same
same
same
same
same
same
same
changed
same
same
same
same
same
same
same
same
same
same
same
changed
same
same
same
same
same
same
same
same
same
same
same
same
same
same
same
same
same
same
same
same
same
same
same
same
same
same
same
same
same
same
same
same
same
same
same
changed
same
same
same
same
same
same
same
same
same
same
changed
same
same
same
same
same
same
same
same
same
same
same
same
same
same
same
